Exception in thread Thread-5:
Traceback (most recent call last):
  File "/root/.virtualenvs/auto_test/lib/python3.6/site-packages/urllib3/connectionpool.py", line 677, in urlopen
    chunked=chunked,
  File "/root/.virtualenvs/auto_test/lib/python3.6/site-packages/urllib3/connectionpool.py", line 426, in _make_request
    six.raise_from(e, None)
  File "<string>", line 3, in raise_from
  File "/root/.virtualenvs/auto_test/lib/python3.6/site-packages/urllib3/connectionpool.py", line 421, in _make_request
    httplib_response = conn.getresponse()
  File "/usr/local/python3/lib/python3.6/http/client.py", line 1331, in getresponse
    response.begin()
  File "/usr/local/python3/lib/python3.6/http/client.py", line 297, in begin
    version, status, reason = self._read_status()
  File "/usr/local/python3/lib/python3.6/http/client.py", line 266, in _read_status
    raise RemoteDisconnected("Remote end closed connection without"
http.client.RemoteDisconnected: Remote end closed connection without response

During handling of the above exception, another exception occurred:

Traceback (most recent call last):
  File "/root/.virtualenvs/auto_test/lib/python3.6/site-packages/requests/adapters.py", line 449, in send
    timeout=timeout
  File "/root/.virtualenvs/auto_test/lib/python3.6/site-packages/urllib3/connectionpool.py", line 725, in urlopen
    method, url, error=e, _pool=self, _stacktrace=sys.exc_info()[2]
  File "/root/.virtualenvs/auto_test/lib/python3.6/site-packages/urllib3/util/retry.py", line 403, in increment
    raise six.reraise(type(error), error, _stacktrace)
  File "/root/.virtualenvs/auto_test/lib/python3.6/site-packages/urllib3/packages/six.py", line 734, in reraise
    raise value.with_traceback(tb)
  File "/root/.virtualenvs/auto_test/lib/python3.6/site-packages/urllib3/connectionpool.py", line 677, in urlopen
    chunked=chunked,
  File "/root/.virtualenvs/auto_test/lib/python3.6/site-packages/urllib3/connectionpool.py", line 426, in _make_request
    six.raise_from(e, None)
  File "<string>", line 3, in raise_from
  File "/root/.virtualenvs/auto_test/lib/python3.6/site-packages/urllib3/connectionpool.py", line 421, in _make_request
    httplib_response = conn.getresponse()
  File "/usr/local/python3/lib/python3.6/http/client.py", line 1331, in getresponse
    response.begin()
  File "/usr/local/python3/lib/python3.6/http/client.py", line 297, in begin
    version, status, reason = self._read_status()
  File "/usr/local/python3/lib/python3.6/http/client.py", line 266, in _read_status
    raise RemoteDisconnected("Remote end closed connection without"
urllib3.exceptions.ProtocolError: ('Connection aborted.', RemoteDisconnected('Remote end closed connection without response',))

During handling of the above exception, another exception occurred:

Traceback (most recent call last):
  File "/usr/local/python3/lib/python3.6/threading.py", line 916, in _bootstrap_inner
    self.run()
  File "/usr/local/python3/lib/python3.6/threading.py", line 864, in run
    self._target(*self._args, **self._kwargs)
  File "./bin/network_query_cron.py", line 25, in call_exec_network_query
    requests.post('http://127.0.0.1:8000/network_query/exec_network_query_task/', data=payload)
  File "/root/.virtualenvs/auto_test/lib/python3.6/site-packages/requests/api.py", line 119, in post
    return request('post', url, data=data, json=json, **kwargs)
  File "/root/.virtualenvs/auto_test/lib/python3.6/site-packages/requests/api.py", line 61, in request
    return session.request(method=method, url=url, **kwargs)
  File "/root/.virtualenvs/auto_test/lib/python3.6/site-packages/requests/sessions.py", line 530, in request
    resp = self.send(prep, **send_kwargs)
  File "/root/.virtualenvs/auto_test/lib/python3.6/site-packages/requests/sessions.py", line 643, in send
    r = adapter.send(request, **kwargs)
  File "/root/.virtualenvs/auto_test/lib/python3.6/site-packages/requests/adapters.py", line 498, in send
    raise ConnectionError(err, request=request)
requests.exceptions.ConnectionError: ('Connection aborted.', RemoteDisconnected('Remote end closed connection without response',))

Exception in thread Thread-6:
Traceback (most recent call last):
  File "/root/.virtualenvs/auto_test/lib/python3.6/site-packages/urllib3/connection.py", line 160, in _new_conn
    (self._dns_host, self.port), self.timeout, **extra_kw
  File "/root/.virtualenvs/auto_test/lib/python3.6/site-packages/urllib3/util/connection.py", line 84, in create_connection
    raise err
  File "/root/.virtualenvs/auto_test/lib/python3.6/site-packages/urllib3/util/connection.py", line 74, in create_connection
    sock.connect(sa)
ConnectionRefusedError: [Errno 111] Connection refused

During handling of the above exception, another exception occurred:

Traceback (most recent call last):
  File "/root/.virtualenvs/auto_test/lib/python3.6/site-packages/urllib3/connectionpool.py", line 677, in urlopen
    chunked=chunked,
  File "/root/.virtualenvs/auto_test/lib/python3.6/site-packages/urllib3/connectionpool.py", line 392, in _make_request
    conn.request(method, url, **httplib_request_kw)
  File "/usr/local/python3/lib/python3.6/http/client.py", line 1239, in request
    self._send_request(method, url, body, headers, encode_chunked)
  File "/usr/local/python3/lib/python3.6/http/client.py", line 1285, in _send_request
    self.endheaders(body, encode_chunked=encode_chunked)
  File "/usr/local/python3/lib/python3.6/http/client.py", line 1234, in endheaders
    self._send_output(message_body, encode_chunked=encode_chunked)
  File "/usr/local/python3/lib/python3.6/http/client.py", line 1026, in _send_output
    self.send(msg)
  File "/usr/local/python3/lib/python3.6/http/client.py", line 964, in send
    self.connect()
  File "/root/.virtualenvs/auto_test/lib/python3.6/site-packages/urllib3/connection.py", line 187, in connect
    conn = self._new_conn()
  File "/root/.virtualenvs/auto_test/lib/python3.6/site-packages/urllib3/connection.py", line 172, in _new_conn
    self, "Failed to establish a new connection: %s" % e
urllib3.exceptions.NewConnectionError: <urllib3.connection.HTTPConnection object at 0x7f5d3591bf28>: Failed to establish a new connection: [Errno 111] Connection refused

During handling of the above exception, another exception occurred:

Traceback (most recent call last):
  File "/root/.virtualenvs/auto_test/lib/python3.6/site-packages/requests/adapters.py", line 449, in send
    timeout=timeout
  File "/root/.virtualenvs/auto_test/lib/python3.6/site-packages/urllib3/connectionpool.py", line 725, in urlopen
    method, url, error=e, _pool=self, _stacktrace=sys.exc_info()[2]
  File "/root/.virtualenvs/auto_test/lib/python3.6/site-packages/urllib3/util/retry.py", line 439, in increment
    raise MaxRetryError(_pool, url, error or ResponseError(cause))
urllib3.exceptions.MaxRetryError: HTTPConnectionPool(host='127.0.0.1', port=8000): Max retries exceeded with url: /network_query/exec_network_query_task/ (Caused by NewConnectionError('<urllib3.connection.HTTPConnection object at 0x7f5d3591bf28>: Failed to establish a new connection: [Errno 111] Connection refused',))

During handling of the above exception, another exception occurred:

Traceback (most recent call last):
  File "/usr/local/python3/lib/python3.6/threading.py", line 916, in _bootstrap_inner
    self.run()
  File "/usr/local/python3/lib/python3.6/threading.py", line 864, in run
    self._target(*self._args, **self._kwargs)
  File "./bin/network_query_cron.py", line 25, in call_exec_network_query
    requests.post('http://127.0.0.1:8000/network_query/exec_network_query_task/', data=payload)
  File "/root/.virtualenvs/auto_test/lib/python3.6/site-packages/requests/api.py", line 119, in post
    return request('post', url, data=data, json=json, **kwargs)
  File "/root/.virtualenvs/auto_test/lib/python3.6/site-packages/requests/api.py", line 61, in request
    return session.request(method=method, url=url, **kwargs)
  File "/root/.virtualenvs/auto_test/lib/python3.6/site-packages/requests/sessions.py", line 530, in request
    resp = self.send(prep, **send_kwargs)
  File "/root/.virtualenvs/auto_test/lib/python3.6/site-packages/requests/sessions.py", line 643, in send
    r = adapter.send(request, **kwargs)
  File "/root/.virtualenvs/auto_test/lib/python3.6/site-packages/requests/adapters.py", line 516, in send
    raise ConnectionError(e, request=request)
requests.exceptions.ConnectionError: HTTPConnectionPool(host='127.0.0.1', port=8000): Max retries exceeded with url: /network_query/exec_network_query_task/ (Caused by NewConnectionError('<urllib3.connection.HTTPConnection object at 0x7f5d3591bf28>: Failed to establish a new connection: [Errno 111] Connection refused',))
